WARNING:torch.distributed.run:
*****************************************
Setting OMP_NUM_THREADS environment variable for each process to be 1 in default, to avoid your system being overloaded, please further tune the variable for optimal performance in your application as needed. 
*****************************************
WARNING: No training data specified
WARNING: No training data specified
WARNING: No training data specified
WARNING: No training data specified
WARNING: No training data specified
using world size: 8 and model-parallel size: 8 
> padded vocab (size: 150528) with 0 dummy tokens (new size: 150528)
WARNING: No training data specified
WARNING: No training data specified
WARNING: No training data specified
> initializing model parallel with size 8
> Loading task configs
    Task CROWS_test loaded from config tasks/ethnic/CROWS_test.yaml
> Successfully load 1 task
> Set tokenizer as a icetk-glm-130B tokenizer! Now you can get_tokenizer() everywhere.
global rank 6 is loading checkpoint /mnt/yrfs/aohan/checkpoints/glm-130b-sat/49300/mp_rank_06_model_states.ptglobal rank 7 is loading checkpoint /mnt/yrfs/aohan/checkpoints/glm-130b-sat/49300/mp_rank_07_model_states.ptglobal rank 3 is loading checkpoint /mnt/yrfs/aohan/checkpoints/glm-130b-sat/49300/mp_rank_03_model_states.pt


global rank 4 is loading checkpoint /mnt/yrfs/aohan/checkpoints/glm-130b-sat/49300/mp_rank_04_model_states.pt
global rank 2 is loading checkpoint /mnt/yrfs/aohan/checkpoints/glm-130b-sat/49300/mp_rank_02_model_states.pt
global rank 5 is loading checkpoint /mnt/yrfs/aohan/checkpoints/glm-130b-sat/49300/mp_rank_05_model_states.pt
global rank 0 is loading checkpoint /mnt/yrfs/aohan/checkpoints/glm-130b-sat/49300/mp_rank_00_model_states.pt
global rank 1 is loading checkpoint /mnt/yrfs/aohan/checkpoints/glm-130b-sat/49300/mp_rank_01_model_states.pt
  successfully loaded /mnt/yrfs/aohan/checkpoints/glm-130b-sat/49300/mp_rank_02_model_states.pt
  successfully loaded /mnt/yrfs/aohan/checkpoints/glm-130b-sat/49300/mp_rank_01_model_states.pt
  successfully loaded /mnt/yrfs/aohan/checkpoints/glm-130b-sat/49300/mp_rank_06_model_states.pt
  successfully loaded /mnt/yrfs/aohan/checkpoints/glm-130b-sat/49300/mp_rank_04_model_states.pt
  successfully loaded /mnt/yrfs/aohan/checkpoints/glm-130b-sat/49300/mp_rank_07_model_states.pt
  successfully loaded /mnt/yrfs/aohan/checkpoints/glm-130b-sat/49300/mp_rank_03_model_states.pt
  successfully loaded /mnt/yrfs/aohan/checkpoints/glm-130b-sat/49300/mp_rank_05_model_states.pt
  successfully loaded /mnt/yrfs/aohan/checkpoints/glm-130b-sat/49300/mp_rank_00_model_states.pt
> Checkpoint loaded in 22.7s


CrowsPairTaskConfig(name='CROWS_test', type=<TaskType.MULTICHOICE: 'mul'>, path='data/CROWS', module='evaluation.CrowsPairTask', metrics=['CP'], use_task_mask=False, use_multitask_encoding=False, unidirectional=False, max_seq_length=2048, file_pattern={'test': '**/CROWS_100.jsonl'}, micro_batch_size=1)
Evaluating task CROWS_test:
    Evaluating group test:
Traceback (most recent call last):
  File "/mnt/yrfs/xuyifan/GLM-130B/evaluate.py", line 67, in <module>
    main()
  File "/mnt/yrfs/xuyifan/GLM-130B/evaluate.py", line 62, in main
    evaluate_all_tasks(args.data_path, model, tokenizer, args.task, task_classes)
  File "/mnt/yrfs/xuyifan/GLM-130B/evaluate.py", line 36, in evaluate_all_tasks
    task.evaluate()
  File "/mnt/yrfs/xuyifan/GLM-130B/evaluation/tasks.py", line 253, in evaluate
    for _, batch in enumerate(dataloader):
  File "/mnt/yrfs/qinkai/miniconda3/envs/largescale/lib/python3.9/site-packages/torch/utils/data/dataloader.py", line 652, in __next__
    data = self._next_data()
  File "/mnt/yrfs/qinkai/miniconda3/envs/largescale/lib/python3.9/site-packages/torch/utils/data/dataloader.py", line 1347, in _next_data
    return self._process_data(data)
  File "/mnt/yrfs/qinkai/miniconda3/envs/largescale/lib/python3.9/site-packages/torch/utils/data/dataloader.py", line 1373, in _process_data
    data.reraise()
  File "/mnt/yrfs/qinkai/miniconda3/envs/largescale/lib/python3.9/site-packages/torch/_utils.py", line 461, in reraise
Traceback (most recent call last):
  File "/mnt/yrfs/xuyifan/GLM-130B/evaluate.py", line 67, in <module>
    raise exception
TypeError: Caught TypeError in DataLoader worker process 0.
Original Traceback (most recent call last):
  File "/mnt/yrfs/qinkai/miniconda3/envs/largescale/lib/python3.9/site-packages/torch/utils/data/_utils/worker.py", line 302, in _worker_loop
    data = fetcher.fetch(index)
  File "/mnt/yrfs/qinkai/miniconda3/envs/largescale/lib/python3.9/site-packages/torch/utils/data/_utils/fetch.py", line 49, in fetch
    data = [self.dataset[idx] for idx in possibly_batched_index]
  File "/mnt/yrfs/qinkai/miniconda3/envs/largescale/lib/python3.9/site-packages/torch/utils/data/_utils/fetch.py", line 49, in <listcomp>
    data = [self.dataset[idx] for idx in possibly_batched_index]
  File "/mnt/yrfs/xuyifan/GLM-130B/evaluation/dataset.py", line 263, in __getitem__
    sample = self.build_multiple_choice_sample(
  File "/mnt/yrfs/xuyifan/GLM-130B/evaluation/dataset.py", line 245, in build_multiple_choice_sample
    print(token.size(),attention_mask.size())
TypeError: 'int' object is not callable

    main()
  File "/mnt/yrfs/xuyifan/GLM-130B/evaluate.py", line 62, in main
    evaluate_all_tasks(args.data_path, model, tokenizer, args.task, task_classes)
  File "/mnt/yrfs/xuyifan/GLM-130B/evaluate.py", line 36, in evaluate_all_tasks
    task.evaluate()
  File "/mnt/yrfs/xuyifan/GLM-130B/evaluation/tasks.py", line 253, in evaluate
    for _, batch in enumerate(dataloader):
  File "/mnt/yrfs/qinkai/miniconda3/envs/largescale/lib/python3.9/site-packages/torch/utils/data/dataloader.py", line 652, in __next__
    data = self._next_data()
  File "/mnt/yrfs/qinkai/miniconda3/envs/largescale/lib/python3.9/site-packages/torch/utils/data/dataloader.py", line 1347, in _next_data
    return self._process_data(data)
  File "/mnt/yrfs/qinkai/miniconda3/envs/largescale/lib/python3.9/site-packages/torch/utils/data/dataloader.py", line 1373, in _process_data
    data.reraise()
  File "/mnt/yrfs/qinkai/miniconda3/envs/largescale/lib/python3.9/site-packages/torch/_utils.py", line 461, in reraise
    raise exception
TypeError: Caught TypeError in DataLoader worker process 0.
Original Traceback (most recent call last):
  File "/mnt/yrfs/qinkai/miniconda3/envs/largescale/lib/python3.9/site-packages/torch/utils/data/_utils/worker.py", line 302, in _worker_loop
    data = fetcher.fetch(index)
  File "/mnt/yrfs/qinkai/miniconda3/envs/largescale/lib/python3.9/site-packages/torch/utils/data/_utils/fetch.py", line 49, in fetch
    data = [self.dataset[idx] for idx in possibly_batched_index]
  File "/mnt/yrfs/qinkai/miniconda3/envs/largescale/lib/python3.9/site-packages/torch/utils/data/_utils/fetch.py", line 49, in <listcomp>
    data = [self.dataset[idx] for idx in possibly_batched_index]
  File "/mnt/yrfs/xuyifan/GLM-130B/evaluation/dataset.py", line 263, in __getitem__
    sample = self.build_multiple_choice_sample(
  File "/mnt/yrfs/xuyifan/GLM-130B/evaluation/dataset.py", line 245, in build_multiple_choice_sample
    print(token.size(),attention_mask.size())
TypeError: 'int' object is not callable

Traceback (most recent call last):
  File "/mnt/yrfs/xuyifan/GLM-130B/evaluate.py", line 67, in <module>
    main()
  File "/mnt/yrfs/xuyifan/GLM-130B/evaluate.py", line 62, in main
    evaluate_all_tasks(args.data_path, model, tokenizer, args.task, task_classes)
  File "/mnt/yrfs/xuyifan/GLM-130B/evaluate.py", line 36, in evaluate_all_tasks
    task.evaluate()
  File "/mnt/yrfs/xuyifan/GLM-130B/evaluation/tasks.py", line 253, in evaluate
    for _, batch in enumerate(dataloader):
  File "/mnt/yrfs/qinkai/miniconda3/envs/largescale/lib/python3.9/site-packages/torch/utils/data/dataloader.py", line 652, in __next__
    data = self._next_data()
  File "/mnt/yrfs/qinkai/miniconda3/envs/largescale/lib/python3.9/site-packages/torch/utils/data/dataloader.py", line 1347, in _next_data
    return self._process_data(data)
  File "/mnt/yrfs/qinkai/miniconda3/envs/largescale/lib/python3.9/site-packages/torch/utils/data/dataloader.py", line 1373, in _process_data
    data.reraise()
  File "/mnt/yrfs/qinkai/miniconda3/envs/largescale/lib/python3.9/site-packages/torch/_utils.py", line 461, in reraise
    raise exception
TypeError: Caught TypeError in DataLoader worker process 0.
Original Traceback (most recent call last):
  File "/mnt/yrfs/qinkai/miniconda3/envs/largescale/lib/python3.9/site-packages/torch/utils/data/_utils/worker.py", line 302, in _worker_loop
    data = fetcher.fetch(index)
  File "/mnt/yrfs/qinkai/miniconda3/envs/largescale/lib/python3.9/site-packages/torch/utils/data/_utils/fetch.py", line 49, in fetch
    data = [self.dataset[idx] for idx in possibly_batched_index]
  File "/mnt/yrfs/qinkai/miniconda3/envs/largescale/lib/python3.9/site-packages/torch/utils/data/_utils/fetch.py", line 49, in <listcomp>
    data = [self.dataset[idx] for idx in possibly_batched_index]
  File "/mnt/yrfs/xuyifan/GLM-130B/evaluation/dataset.py", line 263, in __getitem__
    sample = self.build_multiple_choice_sample(
  File "/mnt/yrfs/xuyifan/GLM-130B/evaluation/dataset.py", line 245, in build_multiple_choice_sample
    print(token.size(),attention_mask.size())
TypeError: 'int' object is not callable

Traceback (most recent call last):
  File "/mnt/yrfs/xuyifan/GLM-130B/evaluate.py", line 67, in <module>
    main()
  File "/mnt/yrfs/xuyifan/GLM-130B/evaluate.py", line 62, in main
    evaluate_all_tasks(args.data_path, model, tokenizer, args.task, task_classes)
  File "/mnt/yrfs/xuyifan/GLM-130B/evaluate.py", line 36, in evaluate_all_tasks
    task.evaluate()
  File "/mnt/yrfs/xuyifan/GLM-130B/evaluation/tasks.py", line 253, in evaluate
    for _, batch in enumerate(dataloader):
  File "/mnt/yrfs/qinkai/miniconda3/envs/largescale/lib/python3.9/site-packages/torch/utils/data/dataloader.py", line 652, in __next__
    data = self._next_data()
  File "/mnt/yrfs/qinkai/miniconda3/envs/largescale/lib/python3.9/site-packages/torch/utils/data/dataloader.py", line 1347, in _next_data
    return self._process_data(data)
  File "/mnt/yrfs/qinkai/miniconda3/envs/largescale/lib/python3.9/site-packages/torch/utils/data/dataloader.py", line 1373, in _process_data
    data.reraise()
  File "/mnt/yrfs/qinkai/miniconda3/envs/largescale/lib/python3.9/site-packages/torch/_utils.py", line 461, in reraise
    raise exception
TypeError: Caught TypeError in DataLoader worker process 0.
Original Traceback (most recent call last):
  File "/mnt/yrfs/qinkai/miniconda3/envs/largescale/lib/python3.9/site-packages/torch/utils/data/_utils/worker.py", line 302, in _worker_loop
    data = fetcher.fetch(index)
  File "/mnt/yrfs/qinkai/miniconda3/envs/largescale/lib/python3.9/site-packages/torch/utils/data/_utils/fetch.py", line 49, in fetch
    data = [self.dataset[idx] for idx in possibly_batched_index]
  File "/mnt/yrfs/qinkai/miniconda3/envs/largescale/lib/python3.9/site-packages/torch/utils/data/_utils/fetch.py", line 49, in <listcomp>
    data = [self.dataset[idx] for idx in possibly_batched_index]
  File "/mnt/yrfs/xuyifan/GLM-130B/evaluation/dataset.py", line 263, in __getitem__
    sample = self.build_multiple_choice_sample(
  File "/mnt/yrfs/xuyifan/GLM-130B/evaluation/dataset.py", line 245, in build_multiple_choice_sample
    print(token.size(),attention_mask.size())
TypeError: 'int' object is not callable

Traceback (most recent call last):
  File "/mnt/yrfs/xuyifan/GLM-130B/evaluate.py", line 67, in <module>
    main()
  File "/mnt/yrfs/xuyifan/GLM-130B/evaluate.py", line 62, in main
    evaluate_all_tasks(args.data_path, model, tokenizer, args.task, task_classes)
  File "/mnt/yrfs/xuyifan/GLM-130B/evaluate.py", line 36, in evaluate_all_tasks
    task.evaluate()
  File "/mnt/yrfs/xuyifan/GLM-130B/evaluation/tasks.py", line 253, in evaluate
    for _, batch in enumerate(dataloader):
  File "/mnt/yrfs/qinkai/miniconda3/envs/largescale/lib/python3.9/site-packages/torch/utils/data/dataloader.py", line 652, in __next__
    data = self._next_data()
  File "/mnt/yrfs/qinkai/miniconda3/envs/largescale/lib/python3.9/site-packages/torch/utils/data/dataloader.py", line 1347, in _next_data
    return self._process_data(data)
  File "/mnt/yrfs/qinkai/miniconda3/envs/largescale/lib/python3.9/site-packages/torch/utils/data/dataloader.py", line 1373, in _process_data
    data.reraise()
  File "/mnt/yrfs/qinkai/miniconda3/envs/largescale/lib/python3.9/site-packages/torch/_utils.py", line 461, in reraise
    raise exception
TypeError: Caught TypeError in DataLoader worker process 0.
Original Traceback (most recent call last):
  File "/mnt/yrfs/qinkai/miniconda3/envs/largescale/lib/python3.9/site-packages/torch/utils/data/_utils/worker.py", line 302, in _worker_loop
    data = fetcher.fetch(index)
  File "/mnt/yrfs/qinkai/miniconda3/envs/largescale/lib/python3.9/site-packages/torch/utils/data/_utils/fetch.py", line 49, in fetch
    data = [self.dataset[idx] for idx in possibly_batched_index]
  File "/mnt/yrfs/qinkai/miniconda3/envs/largescale/lib/python3.9/site-packages/torch/utils/data/_utils/fetch.py", line 49, in <listcomp>
    data = [self.dataset[idx] for idx in possibly_batched_index]
  File "/mnt/yrfs/xuyifan/GLM-130B/evaluation/dataset.py", line 263, in __getitem__
    sample = self.build_multiple_choice_sample(
  File "/mnt/yrfs/xuyifan/GLM-130B/evaluation/dataset.py", line 245, in build_multiple_choice_sample
    print(token.size(),attention_mask.size())
TypeError: 'int' object is not callable

Traceback (most recent call last):
  File "/mnt/yrfs/xuyifan/GLM-130B/evaluate.py", line 67, in <module>
Traceback (most recent call last):
  File "/mnt/yrfs/xuyifan/GLM-130B/evaluate.py", line 67, in <module>
    main()
  File "/mnt/yrfs/xuyifan/GLM-130B/evaluate.py", line 62, in main
    evaluate_all_tasks(args.data_path, model, tokenizer, args.task, task_classes)
  File "/mnt/yrfs/xuyifan/GLM-130B/evaluate.py", line 36, in evaluate_all_tasks
    main()
  File "/mnt/yrfs/xuyifan/GLM-130B/evaluate.py", line 62, in main
    task.evaluate()
  File "/mnt/yrfs/xuyifan/GLM-130B/evaluation/tasks.py", line 253, in evaluate
    evaluate_all_tasks(args.data_path, model, tokenizer, args.task, task_classes)
  File "/mnt/yrfs/xuyifan/GLM-130B/evaluate.py", line 36, in evaluate_all_tasks
    for _, batch in enumerate(dataloader):
  File "/mnt/yrfs/qinkai/miniconda3/envs/largescale/lib/python3.9/site-packages/torch/utils/data/dataloader.py", line 652, in __next__
    task.evaluate()
  File "/mnt/yrfs/xuyifan/GLM-130B/evaluation/tasks.py", line 253, in evaluate
    for _, batch in enumerate(dataloader):
  File "/mnt/yrfs/qinkai/miniconda3/envs/largescale/lib/python3.9/site-packages/torch/utils/data/dataloader.py", line 652, in __next__
    data = self._next_data()
  File "/mnt/yrfs/qinkai/miniconda3/envs/largescale/lib/python3.9/site-packages/torch/utils/data/dataloader.py", line 1347, in _next_data
    data = self._next_data()
  File "/mnt/yrfs/qinkai/miniconda3/envs/largescale/lib/python3.9/site-packages/torch/utils/data/dataloader.py", line 1347, in _next_data
    return self._process_data(data)
  File "/mnt/yrfs/qinkai/miniconda3/envs/largescale/lib/python3.9/site-packages/torch/utils/data/dataloader.py", line 1373, in _process_data
    return self._process_data(data)
  File "/mnt/yrfs/qinkai/miniconda3/envs/largescale/lib/python3.9/site-packages/torch/utils/data/dataloader.py", line 1373, in _process_data
    data.reraise()
  File "/mnt/yrfs/qinkai/miniconda3/envs/largescale/lib/python3.9/site-packages/torch/_utils.py", line 461, in reraise
    data.reraise()
  File "/mnt/yrfs/qinkai/miniconda3/envs/largescale/lib/python3.9/site-packages/torch/_utils.py", line 461, in reraise
    raise exception
TypeError: Caught TypeError in DataLoader worker process 0.
Original Traceback (most recent call last):
  File "/mnt/yrfs/qinkai/miniconda3/envs/largescale/lib/python3.9/site-packages/torch/utils/data/_utils/worker.py", line 302, in _worker_loop
    data = fetcher.fetch(index)
  File "/mnt/yrfs/qinkai/miniconda3/envs/largescale/lib/python3.9/site-packages/torch/utils/data/_utils/fetch.py", line 49, in fetch
    data = [self.dataset[idx] for idx in possibly_batched_index]
  File "/mnt/yrfs/qinkai/miniconda3/envs/largescale/lib/python3.9/site-packages/torch/utils/data/_utils/fetch.py", line 49, in <listcomp>
    data = [self.dataset[idx] for idx in possibly_batched_index]
  File "/mnt/yrfs/xuyifan/GLM-130B/evaluation/dataset.py", line 263, in __getitem__
    sample = self.build_multiple_choice_sample(
  File "/mnt/yrfs/xuyifan/GLM-130B/evaluation/dataset.py", line 245, in build_multiple_choice_sample
    print(token.size(),attention_mask.size())
TypeError: 'int' object is not callable

    raise exception
TypeError: Caught TypeError in DataLoader worker process 0.
Original Traceback (most recent call last):
  File "/mnt/yrfs/qinkai/miniconda3/envs/largescale/lib/python3.9/site-packages/torch/utils/data/_utils/worker.py", line 302, in _worker_loop
    data = fetcher.fetch(index)
  File "/mnt/yrfs/qinkai/miniconda3/envs/largescale/lib/python3.9/site-packages/torch/utils/data/_utils/fetch.py", line 49, in fetch
    data = [self.dataset[idx] for idx in possibly_batched_index]
  File "/mnt/yrfs/qinkai/miniconda3/envs/largescale/lib/python3.9/site-packages/torch/utils/data/_utils/fetch.py", line 49, in <listcomp>
    data = [self.dataset[idx] for idx in possibly_batched_index]
  File "/mnt/yrfs/xuyifan/GLM-130B/evaluation/dataset.py", line 263, in __getitem__
    sample = self.build_multiple_choice_sample(
  File "/mnt/yrfs/xuyifan/GLM-130B/evaluation/dataset.py", line 245, in build_multiple_choice_sample
    print(token.size(),attention_mask.size())
TypeError: 'int' object is not callable

Traceback (most recent call last):
  File "/mnt/yrfs/xuyifan/GLM-130B/evaluate.py", line 67, in <module>
    main()
  File "/mnt/yrfs/xuyifan/GLM-130B/evaluate.py", line 62, in main
    evaluate_all_tasks(args.data_path, model, tokenizer, args.task, task_classes)
  File "/mnt/yrfs/xuyifan/GLM-130B/evaluate.py", line 36, in evaluate_all_tasks
    task.evaluate()
  File "/mnt/yrfs/xuyifan/GLM-130B/evaluation/tasks.py", line 253, in evaluate
    for _, batch in enumerate(dataloader):
  File "/mnt/yrfs/qinkai/miniconda3/envs/largescale/lib/python3.9/site-packages/torch/utils/data/dataloader.py", line 652, in __next__
    data = self._next_data()
  File "/mnt/yrfs/qinkai/miniconda3/envs/largescale/lib/python3.9/site-packages/torch/utils/data/dataloader.py", line 1347, in _next_data
    return self._process_data(data)
  File "/mnt/yrfs/qinkai/miniconda3/envs/largescale/lib/python3.9/site-packages/torch/utils/data/dataloader.py", line 1373, in _process_data
    data.reraise()
  File "/mnt/yrfs/qinkai/miniconda3/envs/largescale/lib/python3.9/site-packages/torch/_utils.py", line 461, in reraise
    raise exception
TypeError: Caught TypeError in DataLoader worker process 0.
Original Traceback (most recent call last):
  File "/mnt/yrfs/qinkai/miniconda3/envs/largescale/lib/python3.9/site-packages/torch/utils/data/_utils/worker.py", line 302, in _worker_loop
    data = fetcher.fetch(index)
  File "/mnt/yrfs/qinkai/miniconda3/envs/largescale/lib/python3.9/site-packages/torch/utils/data/_utils/fetch.py", line 49, in fetch
    data = [self.dataset[idx] for idx in possibly_batched_index]
  File "/mnt/yrfs/qinkai/miniconda3/envs/largescale/lib/python3.9/site-packages/torch/utils/data/_utils/fetch.py", line 49, in <listcomp>
    data = [self.dataset[idx] for idx in possibly_batched_index]
  File "/mnt/yrfs/xuyifan/GLM-130B/evaluation/dataset.py", line 263, in __getitem__
    sample = self.build_multiple_choice_sample(
  File "/mnt/yrfs/xuyifan/GLM-130B/evaluation/dataset.py", line 245, in build_multiple_choice_sample
    print(token.size(),attention_mask.size())
TypeError: 'int' object is not callable

ERROR:torch.distributed.elastic.multiprocessing.api:failed (exitcode: 1) local_rank: 0 (pid: 781189) of binary: /mnt/yrfs/qinkai/miniconda3/envs/largescale/bin/python
Traceback (most recent call last):
  File "/mnt/yrfs/qinkai/miniconda3/envs/largescale/bin/torchrun", line 33, in <module>
    sys.exit(load_entry_point('torch==1.12.0', 'console_scripts', 'torchrun')())
  File "/mnt/yrfs/qinkai/miniconda3/envs/largescale/lib/python3.9/site-packages/torch/distributed/elastic/multiprocessing/errors/__init__.py", line 345, in wrapper
    return f(*args, **kwargs)
  File "/mnt/yrfs/qinkai/miniconda3/envs/largescale/lib/python3.9/site-packages/torch/distributed/run.py", line 761, in main
    run(args)
  File "/mnt/yrfs/qinkai/miniconda3/envs/largescale/lib/python3.9/site-packages/torch/distributed/run.py", line 752, in run
    elastic_launch(
  File "/mnt/yrfs/qinkai/miniconda3/envs/largescale/lib/python3.9/site-packages/torch/distributed/launcher/api.py", line 131, in __call__
    return launch_agent(self._config, self._entrypoint, list(args))
  File "/mnt/yrfs/qinkai/miniconda3/envs/largescale/lib/python3.9/site-packages/torch/distributed/launcher/api.py", line 245, in launch_agent
    raise ChildFailedError(
torch.distributed.elastic.multiprocessing.errors.ChildFailedError: 
============================================================
/mnt/yrfs/xuyifan/GLM-130B/evaluate.py FAILED
------------------------------------------------------------
Failures:
[1]:
  time      : 2022-09-26_00:38:28
  host      : node14
  rank      : 1 (local_rank: 1)
  exitcode  : 1 (pid: 781190)
  error_file: <N/A>
  traceback : To enable traceback see: https://pytorch.org/docs/stable/elastic/errors.html
[2]:
  time      : 2022-09-26_00:38:28
  host      : node14
  rank      : 2 (local_rank: 2)
  exitcode  : 1 (pid: 781191)
  error_file: <N/A>
  traceback : To enable traceback see: https://pytorch.org/docs/stable/elastic/errors.html
[3]:
  time      : 2022-09-26_00:38:28
  host      : node14
  rank      : 3 (local_rank: 3)
  exitcode  : 1 (pid: 781192)
  error_file: <N/A>
  traceback : To enable traceback see: https://pytorch.org/docs/stable/elastic/errors.html
[4]:
  time      : 2022-09-26_00:38:28
  host      : node14
  rank      : 4 (local_rank: 4)
  exitcode  : 1 (pid: 781193)
  error_file: <N/A>
  traceback : To enable traceback see: https://pytorch.org/docs/stable/elastic/errors.html
[5]:
  time      : 2022-09-26_00:38:28
  host      : node14
  rank      : 5 (local_rank: 5)
  exitcode  : 1 (pid: 781194)
  error_file: <N/A>
  traceback : To enable traceback see: https://pytorch.org/docs/stable/elastic/errors.html
[6]:
  time      : 2022-09-26_00:38:28
  host      : node14
  rank      : 6 (local_rank: 6)
  exitcode  : 1 (pid: 781197)
  error_file: <N/A>
  traceback : To enable traceback see: https://pytorch.org/docs/stable/elastic/errors.html
[7]:
  time      : 2022-09-26_00:38:28
  host      : node14
  rank      : 7 (local_rank: 7)
  exitcode  : 1 (pid: 781198)
  error_file: <N/A>
  traceback : To enable traceback see: https://pytorch.org/docs/stable/elastic/errors.html
------------------------------------------------------------
Root Cause (first observed failure):
[0]:
  time      : 2022-09-26_00:38:28
  host      : node14
  rank      : 0 (local_rank: 0)
  exitcode  : 1 (pid: 781189)
  error_file: <N/A>
  traceback : To enable traceback see: https://pytorch.org/docs/stable/elastic/errors.html
============================================================
